Workbook
Name _Hlk160785108: 'App Windows o Linux'!#REF!
Name _Hlk185324047: 'App Windows o Linux'!#REF!
Name DeployMode: #REF!
Name ListaApp: #REF!
Name OLE_LINK1: Elenco_ADO_IKAN!#REF!

Sheet Elenco_ADO_IKAN
A1: DETTAGLIO RILASCIO RDMA (inserire nella colonna "C" il nome del pacchetto / pipeline indicato in lettera di rilascio) (le informazioni ricavate nelle colonne "D"-"E"-"F -G-H " possono essere copiate/incollate nelle rispettive colonne del file "RDMA in corso alla data odierna")
A2: Lettera di rilascio | B2: Code Application | C2: Package IKAN ALM - Pipeleine AZURE DEVOPS | D2: Change Ev | E2: Responsabile/Team | F2: Description RDMA | G2: Application | H2: Deploy Mode | I2: PipelineId | J2: Project | K2: Project IKAN ALM | L2: Scheduling time Production | M2: Type | N2: N° SERVICE REQUEST JCL | O2: ESITO PREPROD | P2: ESITO ESERCIZIO
C3: siweb_EVOLUTIVA | D3: {=IFERROR( _xlfn.LET( _xlpm.risultato, IFERROR( _xlfn.XLOOKUP(TRIM(UPPER(G3)), TRIM(UPPER(Applicazioni!$C$1:$C$474)), Applicazioni!$B$1:$B$474 ), _xlfn.XLOOKUP( TRIM(UPPER( INDEX( _xlfn._xlws.FILTER('[1]Dettaglio pacchetti'!$B$1:$B$530, TRIM(UPPER('[1]Dettaglio pacchetti'!$E$1:$E$530))=TRIM(UPPER(G3)), "" ), 1) )), TRIM(UPPER(Applicazioni!$C$1:$C$474)), Applicazioni!$B$1:$B$474 ) ), IF(_xlpm.risultato=0, "", _xlpm.risultato) ), "" )} -> C20260814_0040 | E3: {=IF(TRIM($B3)="SG-ANAGRAFE", "Bugni Batte", IF(TRIM($B3)="DW01A", "Cauda", IFERROR( VLOOKUP( INDEX('[1]Dettaglio pacchetti'!$AB$1:$AB$530, _xlfn.AGGREGATE(15, 6, (ROW($1:$345))/(ISNUMBER(SEARCH('[1]Dettaglio pacchetti'!$AB$1:$AB$530, $C3))), 1) ) & "*", '[1]Dettaglio pacchetti'!$A$1:$I$530, 3, FALSE ), IFERROR(VLOOKUP($C3, '[1]Dettaglio pacchetti'!$A$1:$I$530, 3, FALSE), "") ) ) )} -> TrenoSinistri | F3: {=IF(TRIM($B3)="DW01A", "Rilascio EDW Estrattori", IFERROR( VLOOKUP( INDEX('[1]Dettaglio pacchetti'!$AB$1:$AB$530, _xlfn.AGGREGATE(15, 6, (ROW($1:$345))/(ISNUMBER(SEARCH('[1]Dettaglio pacchetti'!$AB$1:$AB$530, $C3))), 1) ) & "*", '[1]Dettaglio pacchetti'!$A$1:$I$530, 4, FALSE ), IFERROR(VLOOKUP($C3, '[1]Dettaglio pacchetti'!$A$1:$I$530, 4, FALSE), "") ) )} -> Rilascio Sinistri Web | G3: {=IF(TRIM($B3)="DW01A", "EDW - Estrattori", IF(TRIM($B3)="SG-ANAGRAFE", "SIGEA Anagrafe", IFERROR( VLOOKUP( INDEX('[1]Dettaglio pacchetti'!$AB$1:$AB$530, _xlfn.AGGREGATE(15, 6, (ROW($1:$345))/(ISNUMBER(SEARCH('[1]Dettaglio pacchetti'!$AB$1:$AB$530, $C3))), 1) ) & "*", '[1]Dettaglio pacchetti'!$A$1:$I$530, 5, FALSE ), IFERROR(VLOOKUP($C3, '[1]Dettaglio pacchetti'!$A$1:$I$530, 5, FALSE), "") ) ) )} -> SinistriWeb | H3: {=IFERROR( VLOOKUP( INDEX('[1]Dettaglio pacchetti'!$AB$1:$AB$530, _xlfn.AGGREGATE(15, 6, (ROW($1:$345))/(ISNUMBER(SEARCH('[1]Dettaglio pacchetti'!$AB$1:$AB$530, $C3))), 1) ) & "*", '[1]Dettaglio pacchetti'!$A$1:$I$530, 6, FALSE ), IFERROR(VLOOKUP($C3, '[1]Dettaglio pacchetti'!$A$1:$I$530, 6, FALSE), "") )} -> Azure Devops | I3: =IF(OR(AA3="", AB3=""), "", HYPERLINK(AA3, AB3)) -> siweb_EVOLUTIVA | J3: =IF($AC3="", "", IF(ISNUMBER(SEARCH("Ikan", $AD3)), "", HYPERLINK("https://dev.azure.com/realeitesorg/" & $AC3, $AC3) ) ) -> it.grma.claims | K3: =IF($AC3="", "", IF(ISNUMBER(SEARCH("Ikan", $AD3)), $AC3, "" ) ) | L3: {=IFERROR( VLOOKUP( INDEX('[1]Dettaglio pacchetti'!$AB$1:$AB$530, _xlfn.AGGREGATE(15, 6, ROW($1:$345)/(ISNUMBER(SEARCH('[1]Dettaglio pacchetti'!$AB$1:$AB$530, $C3))), 1) ) & "*", '[1]Dettaglio pacchetti'!$A$1:$I$530, 8, FALSE ), IFERROR(VLOOKUP($C3, '[1]Dettaglio pacchetti'!$A$1:$I$530, 8, FALSE), "") )} -> 23.00 | M3: {=IFERROR( VLOOKUP( INDEX('[1]Dettaglio pacchetti'!$AB$1:$AB$530, _xlfn.AGGREGATE(15, 6, ROW($1:$345)/(ISNUMBER(SEARCH('[1]Dettaglio pacchetti'!$AB$1:$AB$530, $C3))), 1) ) & "*", '[1]Dettaglio pacchetti'!$A$1:$I$530, 9, FALSE ), IFERROR(VLOOKUP($C3, '[1]Dettaglio pacchetti'!$A$1:$I$530, 9, FALSE), "") )} -> ear | O3: OK | P3: OK | AA3: {=IFERROR(VLOOKUP(INDEX('[1]Dettaglio pacchetti'!$AB$1:$AB$530, _xlfn.AGGREGATE(15, 6, (ROW($1:$345))/(ISNUMBER(SEARCH('[1]Dettaglio pacchetti'!$AB$1:$AB$530, $C3))), 1)) & "*", '[1]Dettaglio pacchetti'!$A$1:$N$530, 13, FALSE) & "", "")} -> https://dev.azure.com/realeitesorg/it.grma.claims/_build?definitionId=1857 | AB3: {=IF(ISNUMBER(SEARCH("dev.azure.com", AA3)), IFERROR(VLOOKUP(INDEX('[1]Dettaglio pacchetti'!$AB$1:$AB$530, _xlfn.AGGREGATE(15, 6, (ROW($1:$345))/(ISNUMBER(SEARCH('[1]Dettaglio pacchetti'!$AB$1:$AB$530, $C3))), 1)) & "*", '[1]Dettaglio pacchetti'!$A$1:$N$530, 1, FALSE) & "", ""), "")} -> siweb_EVOLUTIVA | AC3: {=IFERROR( VLOOKUP( INDEX('[1]Dettaglio pacchetti'!$AB$1:$AB$530, _xlfn.AGGREGATE(15,6,ROW($1:$345)/(ISNUMBER(SEARCH('[1]Dettaglio pacchetti'!$AB$1:$AB$530,$C3))),1)) & "*", '[1]Dettaglio pacchetti'!$A$1:$I$530, 7, FALSE ), IFERROR(VLOOKUP($C3, '[1]Dettaglio pacchetti'!$A$1:$I$530, 7, FALSE), "") )} -> it.grma.claims | AD3: {=IFERROR( VLOOKUP( INDEX('[1]Dettaglio pacchetti'!$AB$1:$AB$530, _xlfn.AGGREGATE(15,6,ROW($1:$345)/(ISNUMBER(SEARCH('[1]Dettaglio pacchetti'!$AB$1:$AB$530,$C3))),1)) & "*", '[1]Dettaglio pacchetti'!$A$1:$I$530, 6, FALSE ), IFERROR(VLOOKUP($C3, '[1]Dettaglio pacchetti'!$A$1:$I$530, 6, FALSE), "") )} -> Azure Devops
C4: siweb_EVOLUTIVA | D4: {=IFERROR( _xlfn.LET( _xlpm.risultato, IFERROR( _xlfn.XLOOKUP(TRIM(UPPER(G4)), TRIM(UPPER(Applicazioni!$C$1:$C$474)), Applicazioni!$B$1:$B$474 ), _xlfn.XLOOKUP( TRIM(UPPER( INDEX( _xlfn._xlws.FILTER('[1]Dettaglio pacchetti'!$B$1:$B$530, TRIM(UPPER('[1]Dettaglio pacchetti'!$E$1:$E$530))=TRIM(UPPER(G4)), "" ), 1) )), TRIM(UPPER(Applicazioni!$C$1:$C$474)), Applicazioni!$B$1:$B$474 ) ), IF(_xlpm.risultato=0, "", _xlpm.risultato) ), "" )} -> C20260814_0040 | E4: {=IF(TRIM($B4)="SG-ANAGRAFE", "Bugni Batte", IF(TRIM($B4)="DW01A", "Cauda", IFERROR( VLOOKUP( INDEX('[1]Dettaglio pacchetti'!$AB$1:$AB$530, _xlfn.AGGREGATE(15, 6, (ROW($1:$345))/(ISNUMBER(SEARCH('[1]Dettaglio pacchetti'!$AB$1:$AB$530, $C4))), 1) ) & "*", '[1]Dettaglio pacchetti'!$A$1:$I$530, 3, FALSE ), IFERROR(VLOOKUP($C4, '[1]Dettaglio pacchetti'!$A$1:$I$530, 3, FALSE), "") ) ) )} -> TrenoSinistri | F4: {=IF(TRIM($B4)="DW01A", "Rilascio EDW Estrattori", IFERROR( VLOOKUP( INDEX('[1]Dettaglio pacchetti'!$AB$1:$AB$530, _xlfn.AGGREGATE(15, 6, (ROW($1:$345))/(ISNUMBER(SEARCH('[1]Dettaglio pacchetti'!$AB$1:$AB$530, $C4))), 1) ) & "*", '[1]Dettaglio pacchetti'!$A$1:$I$530, 4, FALSE ), IFERROR(VLOOKUP($C4, '[1]Dettaglio pacchetti'!$A$1:$I$530, 4, FALSE), "") ) )} -> Rilascio Sinistri Web | G4: {=IF(TRIM($B4)="DW01A", "EDW - Estrattori", IF(TRIM($B4)="SG-ANAGRAFE", "SIGEA Anagrafe", IFERROR( VLOOKUP( INDEX('[1]Dettaglio pacchetti'!$AB$1:$AB$530, _xlfn.AGGREGATE(15, 6, (ROW($1:$345))/(ISNUMBER(SEARCH('[1]Dettaglio pacchetti'!$AB$1:$AB$530, $C4))), 1) ) & "*", '[1]Dettaglio pacchetti'!$A$1:$I$530, 5, FALSE ), IFERROR(VLOOKUP($C4, '[1]Dettaglio pacchetti'!$A$1:$I$530, 5, FALSE), "") ) ) )} -> SinistriWeb | H4: {=IFERROR( VLOOKUP( INDEX('[1]Dettaglio pacchetti'!$AB$1:$AB$530, _xlfn.AGGREGATE(15, 6, (ROW($1:$345))/(ISNUMBER(SEARCH('[1]Dettaglio pacchetti'!$AB$1:$AB$530, $C4))), 1) ) & "*", '[1]Dettaglio pacchetti'!$A$1:$I$530, 6, FALSE ), IFERROR(VLOOKUP($C4, '[1]Dettaglio pacchetti'!$A$1:$I$530, 6, FALSE), "") )} -> Azure Devops | I4: =IF(OR(AA4="", AB4=""), "", HYPERLINK(AA4, AB4)) -> siweb_EVOLUTIVA | J4: =IF($AC4="", "", IF(ISNUMBER(SEARCH("Ikan", $AD4)), "", HYPERLINK("https://dev.azure.com/realeitesorg/" & $AC4, $AC4) ) ) -> it.grma.claims | K4: =IF($AC4="", "", IF(ISNUMBER(SEARCH("Ikan", $AD4)), $AC4, "" ) ) | L4: {=IFERROR( VLOOKUP( INDEX('[1]Dettaglio pacchetti'!$AB$1:$AB$530, _xlfn.AGGREGATE(15, 6, ROW($1:$345)/(ISNUMBER(SEARCH('[1]Dettaglio pacchetti'!$AB$1:$AB$530, $C4))), 1) ) & "*", '[1]Dettaglio pacchetti'!$A$1:$I$530, 8, FALSE ), IFERROR(VLOOKUP($C4, '[1]Dettaglio pacchetti'!$A$1:$I$530, 8, FALSE), "") )} -> 23.00 | M4: {=IFERROR( VLOOKUP( INDEX('[1]Dettaglio pacchetti'!$AB$1:$AB$530, _xlfn.AGGREGATE(15, 6, ROW($1:$345)/(ISNUMBER(SEARCH('[1]Dettaglio pacchetti'!$AB$1:$AB$530, $C4))), 1) ) & "*", '[1]Dettaglio pacchetti'!$A$1:$I$530, 9, FALSE ), IFERROR(VLOOKUP($C4, '[1]Dettaglio pacchetti'!$A$1:$I$530, 9, FALSE), "") )} -> ear | O4: OK | P4: OK | AA4: {=IFERROR(VLOOKUP(INDEX('[1]Dettaglio pacchetti'!$AB$1:$AB$530, _xlfn.AGGREGATE(15, 6, (ROW($1:$345))/(ISNUMBER(SEARCH('[1]Dettaglio pacchetti'!$AB$1:$AB$530, $C4))), 1)) & "*", '[1]Dettaglio pacchetti'!$A$1:$N$530, 13, FALSE) & "", "")} -> https://dev.azure.com/realeitesorg/it.grma.claims/_build?definitionId=1857 | AB4: {=IF(ISNUMBER(SEARCH("dev.azure.com", AA4)), IFERROR(VLOOKUP(INDEX('[1]Dettaglio pacchetti'!$AB$1:$AB$530, _xlfn.AGGREGATE(15, 6, (ROW($1:$345))/(ISNUMBER(SEARCH('[1]Dettaglio pacchetti'!$AB$1:$AB$530, $C4))), 1)) & "*", '[1]Dettaglio pacchetti'!$A$1:$N$530, 1, FALSE) & "", ""), "")} -> siweb_EVOLUTIVA | AC4: {=IFERROR( VLOOKUP( INDEX('[1]Dettaglio pacchetti'!$AB$1:$AB$530, _xlfn.AGGREGATE(15,6,ROW($1:$345)/(ISNUMBER(SEARCH('[1]Dettaglio pacchetti'!$AB$1:$AB$530,$C4))),1)) & "*", '[1]Dettaglio pacchetti'!$A$1:$I$530, 7, FALSE ), IFERROR(VLOOKUP($C4, '[1]Dettaglio pacchetti'!$A$1:$I$530, 7, FALSE), "") )} -> it.grma.claims | AD4: {=IFERROR( VLOOKUP( INDEX('[1]Dettaglio pacchetti'!$AB$1:$AB$530, _xlfn.AGGREGATE(15,6,ROW($1:$345)/(ISNUMBER(SEARCH('[1]Dettaglio pacchetti'!$AB$1:$AB$530,$C4))),1)) & "*", '[1]Dettaglio pacchetti'!$A$1:$I$530, 6, FALSE ), IFERROR(VLOOKUP($C4, '[1]Dettaglio pacchetti'!$A$1:$I$530, 6, FALSE), "") )} -> Azure Devops
C5: paspo_EVOLUTIVA | D5: {=IFERROR( _xlfn.LET( _xlpm.risultato, IFERROR( _xlfn.XLOOKUP(TRIM(UPPER(G5)), TRIM(UPPER(Applicazioni!$C$1:$C$474)), Applicazioni!$B$1:$B$474 ), _xlfn.XLOOKUP( TRIM(UPPER( INDEX( _xlfn._xlws.FILTER('[1]Dettaglio pacchetti'!$B$1:$B$530, TRIM(UPPER('[1]Dettaglio pacchetti'!$E$1:$E$530))=TRIM(UPPER(G5)), "" ), 1) )), TRIM(UPPER(Applicazioni!$C$1:$C$474)), Applicazioni!$B$1:$B$474 ) ), IF(_xlpm.risultato=0, "", _xlpm.risultato) ), "" )} -> C20260821_0043 | E5: {=IF(TRIM($B5)="SG-ANAGRAFE", "Bugni Batte", IF(TRIM($B5)="DW01A", "Cauda", IFERROR( VLOOKUP( INDEX('[1]Dettaglio pacchetti'!$AB$1:$AB$530, _xlfn.AGGREGATE(15, 6, (ROW($1:$345))/(ISNUMBER(SEARCH('[1]Dettaglio pacchetti'!$AB$1:$AB$530, $C5))), 1) ) & "*", '[1]Dettaglio pacchetti'!$A$1:$I$530, 3, FALSE ), IFERROR(VLOOKUP($C5, '[1]Dettaglio pacchetti'!$A$1:$I$530, 3, FALSE), "") ) ) )} -> Treno Danni | F5: {=IF(TRIM($B5)="DW01A", "Rilascio EDW Estrattori", IFERROR( VLOOKUP( INDEX('[1]Dettaglio pacchetti'!$AB$1:$AB$530, _xlfn.AGGREGATE(15, 6, (ROW($1:$345))/(ISNUMBER(SEARCH('[1]Dettaglio pacchetti'!$AB$1:$AB$530, $C5))), 1) ) & "*", '[1]Dettaglio pacchetti'!$A$1:$I$530, 4, FALSE ), IFERROR(VLOOKUP($C5, '[1]Dettaglio pacchetti'!$A$1:$I$530, 4, FALSE), "") ) )} -> Rilascio Pass Portal 7PASPO | G5: {=IF(TRIM($B5)="DW01A", "EDW - Estrattori", IF(TRIM($B5)="SG-ANAGRAFE", "SIGEA Anagrafe", IFERROR( VLOOKUP( INDEX('[1]Dettaglio pacchetti'!$AB$1:$AB$530, _xlfn.AGGREGATE(15, 6, (ROW($1:$345))/(ISNUMBER(SEARCH('[1]Dettaglio pacchetti'!$AB$1:$AB$530, $C5))), 1) ) & "*", '[1]Dettaglio pacchetti'!$A$1:$I$530, 5, FALSE ), IFERROR(VLOOKUP($C5, '[1]Dettaglio pacchetti'!$A$1:$I$530, 5, FALSE), "") ) ) )} -> Multicanalità - Pass Portal | H5: {=IFERROR( VLOOKUP( INDEX('[1]Dettaglio pacchetti'!$AB$1:$AB$530, _xlfn.AGGREGATE(15, 6, (ROW($1:$345))/(ISNUMBER(SEARCH('[1]Dettaglio pacchetti'!$AB$1:$AB$530, $C5))), 1) ) & "*", '[1]Dettaglio pacchetti'!$A$1:$I$530, 6, FALSE ), IFERROR(VLOOKUP($C5, '[1]Dettaglio pacchetti'!$A$1:$I$530, 6, FALSE), "") )} -> Azure Devops | I5: =IF(OR(AA5="", AB5=""), "", HYPERLINK(AA5, AB5)) -> paspo_EVOLUTIVA | J5: =IF($AC5="", "", IF(ISNUMBER(SEARCH("Ikan", $AD5)), "", HYPERLINK("https://dev.azure.com/realeitesorg/" & $AC5, $AC5) ) ) -> it.grma.rdna | K5: =IF($AC5="", "", IF(ISNUMBER(SEARCH("Ikan", $AD5)), $AC5, "" ) ) | L5: {=IFERROR( VLOOKUP( INDEX('[1]Dettaglio pacchetti'!$AB$1:$AB$530, _xlfn.AGGREGATE(15, 6, ROW($1:$345)/(ISNUMBER(SEARCH('[1]Dettaglio pacchetti'!$AB$1:$AB$530, $C5))), 1) ) & "*", '[1]Dettaglio pacchetti'!$A$1:$I$530, 8, FALSE ), IFERROR(VLOOKUP($C5, '[1]Dettaglio pacchetti'!$A$1:$I$530, 8, FALSE), "") )} -> 23.00 | M5: {=IFERROR( VLOOKUP( INDEX('[1]Dettaglio pacchetti'!$AB$1:$AB$530, _xlfn.AGGREGATE(15, 6, ROW($1:$345)/(ISNUMBER(SEARCH('[1]Dettaglio pacchetti'!$AB$1:$AB$530, $C5))), 1) ) & "*", '[1]Dettaglio pacchetti'!$A$1:$I$530, 9, FALSE ), IFERROR(VLOOKUP($C5, '[1]Dettaglio pacchetti'!$A$1:$I$530, 9, FALSE), "") )} -> ear | O5: OK | P5: OK | AA5: {=IFERROR(VLOOKUP(INDEX('[1]Dettaglio pacchetti'!$AB$1:$AB$530, _xlfn.AGGREGATE(15, 6, (ROW($1:$345))/(ISNUMBER(SEARCH('[1]Dettaglio pacchetti'!$AB$1:$AB$530, $C5))), 1)) & "*", '[1]Dettaglio pacchetti'!$A$1:$N$530, 13, FALSE) & "", "")} -> https://dev.azure.com/realeitesorg/it.grma.rdna/_build?definitionId=4413 | AB5: {=IF(ISNUMBER(SEARCH("dev.azure.com", AA5)), IFERROR(VLOOKUP(INDEX('[1]Dettaglio pacchetti'!$AB$1:$AB$530, _xlfn.AGGREGATE(15, 6, (ROW($1:$345))/(ISNUMBER(SEARCH('[1]Dettaglio pacchetti'!$AB$1:$AB$530, $C5))), 1)) & "*", '[1]Dettaglio pacchetti'!$A$1:$N$530, 1, FALSE) & "", ""), "")} -> paspo_EVOLUTIVA | AC5: {=IFERROR( VLOOKUP( INDEX('[1]Dettaglio pacchetti'!$AB$1:$AB$530, _xlfn.AGGREGATE(15,6,ROW($1:$345)/(ISNUMBER(SEARCH('[1]Dettaglio pacchetti'!$AB$1:$AB$530,$C5))),1)) & "*", '[1]Dettaglio pacchetti'!$A$1:$I$530, 7, FALSE ), IFERROR(VLOOKUP($C5, '[1]Dettaglio pacchetti'!$A$1:$I$530, 7, FALSE), "") )} -> it.grma.rdna | AD5: {=IFERROR( VLOOKUP( INDEX('[1]Dettaglio pacchetti'!$AB$1:$AB$530, _xlfn.AGGREGATE(15,6,ROW($1:$345)/(ISNUMBER(SEARCH('[1]Dettaglio pacchetti'!$AB$1:$AB$530,$C5))),1)) & "*", '[1]Dettaglio pacchetti'!$A$1:$I$530, 6, FALSE ), IFERROR(VLOOKUP($C5, '[1]Dettaglio pacchetti'!$A$1:$I$530, 6, FALSE), "") )} -> Azure Devops
C6: pason_EVOLUTIVA | D6: {=IFERROR( _xlfn.LET( _xlpm.risultato, IFERROR( _xlfn.XLOOKUP(TRIM(UPPER(G6)), TRIM(UPPER(Applicazioni!$C$1:$C$474)), Applicazioni!$B$1:$B$474 ), _xlfn.XLOOKUP( TRIM(UPPER( INDEX( _xlfn._xlws.FILTER('[1]Dettaglio pacchetti'!$B$1:$B$530, TRIM(UPPER('[1]Dettaglio pacchetti'!$E$1:$E$530))=TRIM(UPPER(G6)), "" ), 1) )), TRIM(UPPER(Applicazioni!$C$1:$C$474)), Applicazioni!$B$1:$B$474 ) ), IF(_xlpm.risultato=0, "", _xlpm.risultato) ), "" )} -> C20260820_0046 | E6: {=IF(TRIM($B6)="SG-ANAGRAFE", "Bugni Batte", IF(TRIM($B6)="DW01A", "Cauda", IFERROR( VLOOKUP( INDEX('[1]Dettaglio pacchetti'!$AB$1:$AB$530, _xlfn.AGGREGATE(15, 6, (ROW($1:$345))/(ISNUMBER(SEARCH('[1]Dettaglio pacchetti'!$AB$1:$AB$530, $C6))), 1) ) & "*", '[1]Dettaglio pacchetti'!$A$1:$I$530, 3, FALSE ), IFERROR(VLOOKUP($C6, '[1]Dettaglio pacchetti'!$A$1:$I$530, 3, FALSE), "") ) ) )} -> Treno Danni | F6: {=IF(TRIM($B6)="DW01A", "Rilascio EDW Estrattori", IFERROR( VLOOKUP( INDEX('[1]Dettaglio pacchetti'!$AB$1:$AB$530, _xlfn.AGGREGATE(15, 6, (ROW($1:$345))/(ISNUMBER(SEARCH('[1]Dettaglio pacchetti'!$AB$1:$AB$530, $C6))), 1) ) & "*", '[1]Dettaglio pacchetti'!$A$1:$I$530, 4, FALSE ), IFERROR(VLOOKUP($C6, '[1]Dettaglio pacchetti'!$A$1:$I$530, 4, FALSE), "") ) )} -> Rilascio Pass CompagniaRelease PASON | G6: {=IF(TRIM($B6)="DW01A", "EDW - Estrattori", IF(TRIM($B6)="SG-ANAGRAFE", "SIGEA Anagrafe", IFERROR( VLOOKUP( INDEX('[1]Dettaglio pacchetti'!$AB$1:$AB$530, _xlfn.AGGREGATE(15, 6, (ROW($1:$345))/(ISNUMBER(SEARCH('[1]Dettaglio pacchetti'!$AB$1:$AB$530, $C6))), 1) ) & "*", '[1]Dettaglio pacchetti'!$A$1:$I$530, 5, FALSE ), IFERROR(VLOOKUP($C6, '[1]Dettaglio pacchetti'!$A$1:$I$530, 5, FALSE), "") ) ) )} -> Pass RE | H6: {=IFERROR( VLOOKUP( INDEX('[1]Dettaglio pacchetti'!$AB$1:$AB$530, _xlfn.AGGREGATE(15, 6, (ROW($1:$345))/(ISNUMBER(SEARCH('[1]Dettaglio pacchetti'!$AB$1:$AB$530, $C6))), 1) ) & "*", '[1]Dettaglio pacchetti'!$A$1:$I$530, 6, FALSE ), IFERROR(VLOOKUP($C6, '[1]Dettaglio pacchetti'!$A$1:$I$530, 6, FALSE), "") )} -> Azure Devops | I6: =IF(OR(AA6="", AB6=""), "", HYPERLINK(AA6, AB6)) -> pason_EVOLUTIVA | J6: =IF($AC6="", "", IF(ISNUMBER(SEARCH("Ikan", $AD6)), "", HYPERLINK("https://dev.azure.com/realeitesorg/" & $AC6, $AC6) ) ) -> it.grma.rdna | K6: =IF($AC6="", "", IF(ISNUMBER(SEARCH("Ikan", $AD6)), $AC6, "" ) ) | L6: {=IFERROR( VLOOKUP( INDEX('[1]Dettaglio pacchetti'!$AB$1:$AB$530, _xlfn.AGGREGATE(15, 6, ROW($1:$345)/(ISNUMBER(SEARCH('[1]Dettaglio pacchetti'!$AB$1:$AB$530, $C6))), 1) ) & "*", '[1]Dettaglio pacchetti'!$A$1:$I$530, 8, FALSE ), IFERROR(VLOOKUP($C6, '[1]Dettaglio pacchetti'!$A$1:$I$530, 8, FALSE), "") )} -> 23.00 | M6: {=IFERROR( VLOOKUP( INDEX('[1]Dettaglio pacchetti'!$AB$1:$AB$530, _xlfn.AGGREGATE(15, 6, ROW($1:$345)/(ISNUMBER(SEARCH('[1]Dettaglio pacchetti'!$AB$1:$AB$530, $C6))), 1) ) & "*", '[1]Dettaglio pacchetti'!$A$1:$I$530, 9, FALSE ), IFERROR(VLOOKUP($C6, '[1]Dettaglio pacchetti'!$A$1:$I$530, 9, FALSE), "") )} -> ear | O6: OK | P6: OK | AA6: {=IFERROR(VLOOKUP(INDEX('[1]Dettaglio pacchetti'!$AB$1:$AB$530, _xlfn.AGGREGATE(15, 6, (ROW($1:$345))/(ISNUMBER(SEARCH('[1]Dettaglio pacchetti'!$AB$1:$AB$530, $C6))), 1)) & "*", '[1]Dettaglio pacchetti'!$A$1:$N$530, 13, FALSE) & "", "")} -> https://dev.azure.com/realeitesorg/it.grma.rdna/_build?definitionId=2862 | AB6: {=IF(ISNUMBER(SEARCH("dev.azure.com", AA6)), IFERROR(VLOOKUP(INDEX('[1]Dettaglio pacchetti'!$AB$1:$AB$530, _xlfn.AGGREGATE(15, 6, (ROW($1:$345))/(ISNUMBER(SEARCH('[1]Dettaglio pacchetti'!$AB$1:$AB$530, $C6))), 1)) & "*", '[1]Dettaglio pacchetti'!$A$1:$N$530, 1, FALSE) & "", ""), "")} -> pason_EVOLUTIVA | AC6: {=IFERROR( VLOOKUP( INDEX('[1]Dettaglio pacchetti'!$AB$1:$AB$530, _xlfn.AGGREGATE(15,6,ROW($1:$345)/(ISNUMBER(SEARCH('[1]Dettaglio pacchetti'!$AB$1:$AB$530,$C6))),1)) & "*", '[1]Dettaglio pacchetti'!$A$1:$I$530, 7, FALSE ), IFERROR(VLOOKUP($C6, '[1]Dettaglio pacchetti'!$A$1:$I$530, 7, FALSE), "") )} -> it.grma.rdna | AD6: {=IFERROR( VLOOKUP( INDEX('[1]Dettaglio pacchetti'!$AB$1:$AB$530, _xlfn.AGGREGATE(15,6,ROW($1:$345)/(ISNUMBER(SEARCH('[1]Dettaglio pacchetti'!$AB$1:$AB$530,$C6))),1)) & "*", '[1]Dettaglio pacchetti'!$A$1:$I$530, 6, FALSE ), IFERROR(VLOOKUP($C6, '[1]Dettaglio pacchetti'!$A$1:$I$530, 6, FALSE), "") )} -> Azure Devops
C7: pasba_EVOLUTIVA | D7: {=IFERROR( _xlfn.LET( _xlpm.risultato, IFERROR( _xlfn.XLOOKUP(TRIM(UPPER(G7)), TRIM(UPPER(Applicazioni!$C$1:$C$474)), Applicazioni!$B$1:$B$474 ), _xlfn.XLOOKUP( TRIM(UPPER( INDEX( _xlfn._xlws.FILTER('[1]Dettaglio pacchetti'!$B$1:$B$530, TRIM(UPPER('[1]Dettaglio pacchetti'!$E$1:$E$530))=TRIM(UPPER(G7)), "" ), 1) )), TRIM(UPPER(Applicazioni!$C$1:$C$474)), Applicazioni!$B$1:$B$474 ) ), IF(_xlpm.risultato=0, "", _xlpm.risultato) ), "" )} -> C20260820_0046 | E7: {=IF(TRIM($B7)="SG-ANAGRAFE", "Bugni Batte", IF(TRIM($B7)="DW01A", "Cauda", IFERROR( VLOOKUP( INDEX('[1]Dettaglio pacchetti'!$AB$1:$AB$530, _xlfn.AGGREGATE(15, 6, (ROW($1:$345))/(ISNUMBER(SEARCH('[1]Dettaglio pacchetti'!$AB$1:$AB$530, $C7))), 1) ) & "*", '[1]Dettaglio pacchetti'!$A$1:$I$530, 3, FALSE ), IFERROR(VLOOKUP($C7, '[1]Dettaglio pacchetti'!$A$1:$I$530, 3, FALSE), "") ) ) )} -> Treno Danni | F7: {=IF(TRIM($B7)="DW01A", "Rilascio EDW Estrattori", IFERROR( VLOOKUP( INDEX('[1]Dettaglio pacchetti'!$AB$1:$AB$530, _xlfn.AGGREGATE(15, 6, (ROW($1:$345))/(ISNUMBER(SEARCH('[1]Dettaglio pacchetti'!$AB$1:$AB$530, $C7))), 1) ) & "*", '[1]Dettaglio pacchetti'!$A$1:$I$530, 4, FALSE ), IFERROR(VLOOKUP($C7, '[1]Dettaglio pacchetti'!$A$1:$I$530, 4, FALSE), "") ) )} -> Rilascio Pass compagnia batch PASBA | G7: {=IF(TRIM($B7)="DW01A", "EDW - Estrattori", IF(TRIM($B7)="SG-ANAGRAFE", "SIGEA Anagrafe", IFERROR( VLOOKUP( INDEX('[1]Dettaglio pacchetti'!$AB$1:$AB$530, _xlfn.AGGREGATE(15, 6, (ROW($1:$345))/(ISNUMBER(SEARCH('[1]Dettaglio pacchetti'!$AB$1:$AB$530, $C7))), 1) ) & "*", '[1]Dettaglio pacchetti'!$A$1:$I$530, 5, FALSE ), IFERROR(VLOOKUP($C7, '[1]Dettaglio pacchetti'!$A$1:$I$530, 5, FALSE), "") ) ) )} -> Pass RE - Batch | H7: {=IFERROR( VLOOKUP( INDEX('[1]Dettaglio pacchetti'!$AB$1:$AB$530, _xlfn.AGGREGATE(15, 6, (ROW($1:$345))/(ISNUMBER(SEARCH('[1]Dettaglio pacchetti'!$AB$1:$AB$530, $C7))), 1) ) & "*", '[1]Dettaglio pacchetti'!$A$1:$I$530, 6, FALSE ), IFERROR(VLOOKUP($C7, '[1]Dettaglio pacchetti'!$A$1:$I$530, 6, FALSE), "") )} -> Azure Devops | I7: =IF(OR(AA7="", AB7=""), "", HYPERLINK(AA7, AB7)) -> pasba_EVOLUTIVA | J7: =IF($AC7="", "", IF(ISNUMBER(SEARCH("Ikan", $AD7)), "", HYPERLINK("https://dev.azure.com/realeitesorg/" & $AC7, $AC7) ) ) -> it.grma.rdna | K7: =IF($AC7="", "", IF(ISNUMBER(SEARCH("Ikan", $AD7)), $AC7, "" ) ) | L7: {=IFERROR( VLOOKUP( INDEX('[1]Dettaglio pacchetti'!$AB$1:$AB$530, _xlfn.AGGREGATE(15, 6, ROW($1:$345)/(ISNUMBER(SEARCH('[1]Dettaglio pacchetti'!$AB$1:$AB$530, $C7))), 1) ) & "*", '[1]Dettaglio pacchetti'!$A$1:$I$530, 8, FALSE ), IFERROR(VLOOKUP($C7, '[1]Dettaglio pacchetti'!$A$1:$I$530, 8, FALSE), "") )} -> 22.50 | M7: {=IFERROR( VLOOKUP( INDEX('[1]Dettaglio pacchetti'!$AB$1:$AB$530, _xlfn.AGGREGATE(15, 6, ROW($1:$345)/(ISNUMBER(SEARCH('[1]Dettaglio pacchetti'!$AB$1:$AB$530, $C7))), 1) ) & "*", '[1]Dettaglio pacchetti'!$A$1:$I$530, 9, FALSE ), IFERROR(VLOOKUP($C7, '[1]Dettaglio pacchetti'!$A$1:$I$530, 9, FALSE), "") )} -> ear | O7: OK | P7: OK | AA7: {=IFERROR(VLOOKUP(INDEX('[1]Dettaglio pacchetti'!$AB$1:$AB$530, _xlfn.AGGREGATE(15, 6, (ROW($1:$345))/(ISNUMBER(SEARCH('[1]Dettaglio pacchetti'!$AB$1:$AB$530, $C7))), 1)) & "*", '[1]Dettaglio pacchetti'!$A$1:$N$530, 13, FALSE) & "", "")} -> https://dev.azure.com/realeitesorg/it.grma.rdna/_build?definitionId=2978 | AB7: {=IF(ISNUMBER(SEARCH("dev.azure.com", AA7)), IFERROR(VLOOKUP(INDEX('[1]Dettaglio pacchetti'!$AB$1:$AB$530, _xlfn.AGGREGATE(15, 6, (ROW($1:$345))/(ISNUMBER(SEARCH('[1]Dettaglio pacchetti'!$AB$1:$AB$530, $C7))), 1)) & "*", '[1]Dettaglio pacchetti'!$A$1:$N$530, 1, FALSE) & "", ""), "")} -> pasba_EVOLUTIVA | AC7: {=IFERROR( VLOOKUP( INDEX('[1]Dettaglio pacchetti'!$AB$1:$AB$530, _xlfn.AGGREGATE(15,6,ROW($1:$345)/(ISNUMBER(SEARCH('[1]Dettaglio pacchetti'!$AB$1:$AB$530,$C7))),1)) & "*", '[1]Dettaglio pacchetti'!$A$1:$I$530, 7, FALSE ), IFERROR(VLOOKUP($C7, '[1]Dettaglio pacchetti'!$A$1:$I$530, 7, FALSE), "") )} -> it.grma.rdna | AD7: {=IFERROR( VLOOKUP( INDEX('[1]Dettaglio pacchetti'!$AB$1:$AB$530, _xlfn.AGGREGATE(15,6,ROW($1:$345)/(ISNUMBER(SEARCH('[1]Dettaglio pacchetti'!$AB$1:$AB$530,$C7))),1)) & "*", '[1]Dettaglio pacchetti'!$A$1:$I$530, 6, FALSE ), IFERROR(VLOOKUP($C7, '[1]Dettaglio pacchetti'!$A$1:$I$530, 6, FALSE), "") )} -> Azure Devops
C8: documentum-portafoglio_EVOLUTIVA | D8: {=IFERROR( _xlfn.LET( _xlpm.risultato, IFERROR( _xlfn.XLOOKUP(TRIM(UPPER(G8)), TRIM(UPPER(Applicazioni!$C$1:$C$474)), Applicazioni!$B$1:$B$474 ), _xlfn.XLOOKUP( TRIM(UPPER( INDEX( _xlfn._xlws.FILTER('[1]Dettaglio pacchetti'!$B$1:$B$530, TRIM(UPPER('[1]Dettaglio pacchetti'!$E$1:$E$530))=TRIM(UPPER(G8)), "" ), 1) )), TRIM(UPPER(Applicazioni!$C$1:$C$474)), Applicazioni!$B$1:$B$474 ) ), IF(_xlpm.risultato=0, "", _xlpm.risultato) ), "" )} -> C20260821_0050 | E8: {=IF(TRIM($B8)="SG-ANAGRAFE", "Bugni Batte", IF(TRIM($B8)="DW01A", "Cauda", IFERROR( VLOOKUP( INDEX('[1]Dettaglio pacchetti'!$AB$1:$AB$530, _xlfn.AGGREGATE(15, 6, (ROW($1:$345))/(ISNUMBER(SEARCH('[1]Dettaglio pacchetti'!$AB$1:$AB$530, $C8))), 1) ) & "*", '[1]Dettaglio pacchetti'!$A$1:$I$530, 3, FALSE ), IFERROR(VLOOKUP($C8, '[1]Dettaglio pacchetti'!$A$1:$I$530, 3, FALSE), "") ) ) )} -> Rocca | F8: {=IF(TRIM($B8)="DW01A", "Rilascio EDW Estrattori", IFERROR( VLOOKUP( INDEX('[1]Dettaglio pacchetti'!$AB$1:$AB$530, _xlfn.AGGREGATE(15, 6, (ROW($1:$345))/(ISNUMBER(SEARCH('[1]Dettaglio pacchetti'!$AB$1:$AB$530, $C8))), 1) ) & "*", '[1]Dettaglio pacchetti'!$A$1:$I$530, 4, FALSE ), IFERROR(VLOOKUP($C8, '[1]Dettaglio pacchetti'!$A$1:$I$530, 4, FALSE), "") ) )} -> Rilascio Portale Documentale Portafoglio | G8: {=IF(TRIM($B8)="DW01A", "EDW - Estrattori", IF(TRIM($B8)="SG-ANAGRAFE", "SIGEA Anagrafe", IFERROR( VLOOKUP( INDEX('[1]Dettaglio pacchetti'!$AB$1:$AB$530, _xlfn.AGGREGATE(15, 6, (ROW($1:$345))/(ISNUMBER(SEARCH('[1]Dettaglio pacchetti'!$AB$1:$AB$530, $C8))), 1) ) & "*", '[1]Dettaglio pacchetti'!$A$1:$I$530, 5, FALSE ), IFERROR(VLOOKUP($C8, '[1]Dettaglio pacchetti'!$A$1:$I$530, 5, FALSE), "") ) ) )} -> Portale Documentale Portafoglio | H8: {=IFERROR( VLOOKUP( INDEX('[1]Dettaglio pacchetti'!$AB$1:$AB$530, _xlfn.AGGREGATE(15, 6, (ROW($1:$345))/(ISNUMBER(SEARCH('[1]Dettaglio pacchetti'!$AB$1:$AB$530, $C8))), 1) ) & "*", '[1]Dettaglio pacchetti'!$A$1:$I$530, 6, FALSE ), IFERROR(VLOOKUP($C8, '[1]Dettaglio pacchetti'!$A$1:$I$530, 6, FALSE), "") )} -> Azure Devops | I8: =IF(OR(AA8="", AB8=""), "", HYPERLINK(AA8, AB8)) -> documentum-portafoglio_EVOLUTIVA | J8: =IF($AC8="", "", IF(ISNUMBER(SEARCH("Ikan", $AD8)), "", HYPERLINK("https://dev.azure.com/realeitesorg/" & $AC8, $AC8) ) ) -> it.ites.deploy.documentale | K8: =IF($AC8="", "", IF(ISNUMBER(SEARCH("Ikan", $AD8)), $AC8, "" ) ) | L8: {=IFERROR( VLOOKUP( INDEX('[1]Dettaglio pacchetti'!$AB$1:$AB$530, _xlfn.AGGREGATE(15, 6, ROW($1:$345)/(ISNUMBER(SEARCH('[1]Dettaglio pacchetti'!$AB$1:$AB$530, $C8))), 1) ) & "*", '[1]Dettaglio pacchetti'!$A$1:$I$530, 8, FALSE ), IFERROR(VLOOKUP($C8, '[1]Dettaglio pacchetti'!$A$1:$I$530, 8, FALSE), "") )} -> 23.00 | M8: {=IFERROR( VLOOKUP( INDEX('[1]Dettaglio pacchetti'!$AB$1:$AB$530, _xlfn.AGGREGATE(15, 6, ROW($1:$345)/(ISNUMBER(SEARCH('[1]Dettaglio pacchetti'!$AB$1:$AB$530, $C8))), 1) ) & "*", '[1]Dettaglio pacchetti'!$A$1:$I$530, 9, FALSE ), IFERROR(VLOOKUP($C8, '[1]Dettaglio pacchetti'!$A$1:$I$530, 9, FALSE), "") )} -> ear | O8: OK | P8: OK | AA8: {=IFERROR(VLOOKUP(INDEX('[1]Dettaglio pacchetti'!$AB$1:$AB$530, _xlfn.AGGREGATE(15, 6, (ROW($1:$345))/(ISNUMBER(SEARCH('[1]Dettaglio pacchetti'!$AB$1:$AB$530, $C8))), 1)) & "*", '[1]Dettaglio pacchetti'!$A$1:$N$530, 13, FALSE) & "", "")} -> https://dev.azure.com/realeitesorg/it.ites.infra.deploy.documentale/_build?definitionId=2174 | AB8: {=IF(ISNUMBER(SEARCH("dev.azure.com", AA8)), IFERROR(VLOOKUP(INDEX('[1]Dettaglio pacchetti'!$AB$1:$AB$530, _xlfn.AGGREGATE(15, 6, (ROW($1:$345))/(ISNUMBER(SEARCH('[1]Dettaglio pacchetti'!$AB$1:$AB$530, $C8))), 1)) & "*", '[1]Dettaglio pacchetti'!$A$1:$N$530, 1, FALSE) & "", ""), "")} -> documentum-portafoglio_EVOLUTIVA | AC8: {=IFERROR( VLOOKUP( INDEX('[1]Dettaglio pacchetti'!$AB$1:$AB$530, _xlfn.AGGREGATE(15,6,ROW($1:$345)/(ISNUMBER(SEARCH('[1]Dettaglio pacchetti'!$AB$1:$AB$530,$C8))),1)) & "*", '[1]Dettaglio pacchetti'!$A$1:$I$530, 7, FALSE ), IFERROR(VLOOKUP($C8, '[1]Dettaglio pacchetti'!$A$1:$I$530, 7, FALSE), "") )} -> it.ites.deploy.documentale | AD8: {=IFERROR( VLOOKUP( INDEX('[1]Dettaglio pacchetti'!$AB$1:$AB$530, _xlfn.AGGREGATE(15,6,ROW($1:$345)/(ISNUMBER(SEARCH('[1]Dettaglio pacchetti'!$AB$1:$AB$530,$C8))),1)) & "*", '[1]Dettaglio pacchetti'!$A$1:$I$530, 6, FALSE ), IFERROR(VLOOKUP($C8, '[1]Dettaglio pacchetti'!$A$1:$I$530, 6, FALSE), "") )} -> Azure Devops
C9: deploy.documentale_8emc02a_EVOLUTIVA | D9: {=IFERROR( _xlfn.LET( _xlpm.risultato, IFERROR( _xlfn.XLOOKUP(TRIM(UPPER(G9)), TRIM(UPPER(Applicazioni!$C$1:$C$474)), Applicazioni!$B$1:$B$474 ), _xlfn.XLOOKUP( TRIM(UPPER( INDEX( _xlfn._xlws.FILTER('[1]Dettaglio pacchetti'!$B$1:$B$530, TRIM(UPPER('[1]Dettaglio pacchetti'!$E$1:$E$530))=TRIM(UPPER(G9)), "" ), 1) )), TRIM(UPPER(Applicazioni!$C$1:$C$474)), Applicazioni!$B$1:$B$474 ) ), IF(_xlpm.risultato=0, "", _xlpm.risultato) ), "" )} | E9: {=IF(TRIM($B9)="SG-ANAGRAFE", "Bugni Batte", IF(TRIM($B9)="DW01A", "Cauda", IFERROR( VLOOKUP( INDEX('[1]Dettaglio pacchetti'!$AB$1:$AB$530, _xlfn.AGGREGATE(15, 6, (ROW($1:$345))/(ISNUMBER(SEARCH('[1]Dettaglio pacchetti'!$AB$1:$AB$530, $C9))), 1) ) & "*", '[1]Dettaglio pacchetti'!$A$1:$I$530, 3, FALSE ), IFERROR(VLOOKUP($C9, '[1]Dettaglio pacchetti'!$A$1:$I$530, 3, FALSE), "") ) ) )} -> Rocca | F9: {=IF(TRIM($B9)="DW01A", "Rilascio EDW Estrattori", IFERROR( VLOOKUP( INDEX('[1]Dettaglio pacchetti'!$AB$1:$AB$530, _xlfn.AGGREGATE(15, 6, (ROW($1:$345))/(ISNUMBER(SEARCH('[1]Dettaglio pacchetti'!$AB$1:$AB$530, $C9))), 1) ) & "*", '[1]Dettaglio pacchetti'!$A$1:$I$530, 4, FALSE ), IFERROR(VLOOKUP($C9, '[1]Dettaglio pacchetti'!$A$1:$I$530, 4, FALSE), "") ) )} -> Rilascio Portale DocumentaleSinistri 8EMC02A | G9: {=IF(TRIM($B9)="DW01A", "EDW - Estrattori", IF(TRIM($B9)="SG-ANAGRAFE", "SIGEA Anagrafe", IFERROR( VLOOKUP( INDEX('[1]Dettaglio pacchetti'!$AB$1:$AB$530, _xlfn.AGGREGATE(15, 6, (ROW($1:$345))/(ISNUMBER(SEARCH('[1]Dettaglio pacchetti'!$AB$1:$AB$530, $C9))), 1) ) & "*", '[1]Dettaglio pacchetti'!$A$1:$I$530, 5, FALSE ), IFERROR(VLOOKUP($C9, '[1]Dettaglio pacchetti'!$A$1:$I$530, 5, FALSE), "") ) ) )} -> Portale Documentale Sinistri | H9: {=IFERROR( VLOOKUP( INDEX('[1]Dettaglio pacchetti'!$AB$1:$AB$530, _xlfn.AGGREGATE(15, 6, (ROW($1:$345))/(ISNUMBER(SEARCH('[1]Dettaglio pacchetti'!$AB$1:$AB$530, $C9))), 1) ) & "*", '[1]Dettaglio pacchetti'!$A$1:$I$530, 6, FALSE ), IFERROR(VLOOKUP($C9, '[1]Dettaglio pacchetti'!$A$1:$I$530, 6, FALSE), "") )} -> Azure Devops | I9: =IF(OR(AA9="", AB9=""), "", HYPERLINK(AA9, AB9)) -> deploy.documentale_8emc02a_EVOLUTIVA | J9: =IF($AC9="", "", IF(ISNUMBER(SEARCH("Ikan", $AD9)), "", HYPERLINK("https://dev.azure.com/realeitesorg/" & $AC9, $AC9) ) ) -> it.ites.deploy.documentale | K9: =IF($AC9="", "", IF(ISNUMBER(SEARCH("Ikan", $AD9)), $AC9, "" ) ) | L9: {=IFERROR( VLOOKUP( INDEX('[1]Dettaglio pacchetti'!$AB$1:$AB$530, _xlfn.AGGREGATE(15, 6, ROW($1:$345)/(ISNUMBER(SEARCH('[1]Dettaglio pacchetti'!$AB$1:$AB$530, $C9))), 1) ) & "*", '[1]Dettaglio pacchetti'!$A$1:$I$530, 8, FALSE ), IFERROR(VLOOKUP($C9, '[1]Dettaglio pacchetti'!$A$1:$I$530, 8, FALSE), "") )} -> 23.00 | M9: {=IFERROR( VLOOKUP( INDEX('[1]Dettaglio pacchetti'!$AB$1:$AB$530, _xlfn.AGGREGATE(15, 6, ROW($1:$345)/(ISNUMBER(SEARCH('[1]Dettaglio pacchetti'!$AB$1:$AB$530, $C9))), 1) ) & "*", '[1]Dettaglio pacchetti'!$A$1:$I$530, 9, FALSE ), IFERROR(VLOOKUP($C9, '[1]Dettaglio pacchetti'!$A$1:$I$530, 9, FALSE), "") )} -> ear | O9: OK | P9: OK | AA9: {=IFERROR(VLOOKUP(INDEX('[1]Dettaglio pacchetti'!$AB$1:$AB$530, _xlfn.AGGREGATE(15, 6, (ROW($1:$345))/(ISNUMBER(SEARCH('[1]Dettaglio pacchetti'!$AB$1:$AB$530, $C9))), 1)) & "*", '[1]Dettaglio pacchetti'!$A$1:$N$530, 13, FALSE) & "", "")} -> https://dev.azure.com/realeitesorg/it.ites.deploy.documentale/_build?definitionId=4998 | AB9: {=IF(ISNUMBER(SEARCH("dev.azure.com", AA9)), IFERROR(VLOOKUP(INDEX('[1]Dettaglio pacchetti'!$AB$1:$AB$530, _xlfn.AGGREGATE(15, 6, (ROW($1:$345))/(ISNUMBER(SEARCH('[1]Dettaglio pacchetti'!$AB$1:$AB$530, $C9))), 1)) & "*", '[1]Dettaglio pacchetti'!$A$1:$N$530, 1, FALSE) & "", ""), "")} -> deploy.documentale_8emc02a_EVOLUTIVA | AC9: {=IFERROR( VLOOKUP( INDEX('[1]Dettaglio pacchetti'!$AB$1:$AB$530, _xlfn.AGGREGATE(15,6,ROW($1:$345)/(ISNUMBER(SEARCH('[1]Dettaglio pacchetti'!$AB$1:$AB$530,$C9))),1)) & "*", '[1]Dettaglio pacchetti'!$A$1:$I$530, 7, FALSE ), IFERROR(VLOOKUP($C9, '[1]Dettaglio pacchetti'!$A$1:$I$530, 7, FALSE), "") )} -> it.ites.deploy.documentale | AD9: {=IFERROR( VLOOKUP( INDEX('[1]Dettaglio pacchetti'!$AB$1:$AB$530, _xlfn.AGGREGATE(15,6,ROW($1:$345)/(ISNUMBER(SEARCH('[1]Dettaglio pacchetti'!$AB$1:$AB$530,$C9))),1)) & "*", '[1]Dettaglio pacchetti'!$A$1:$I$530, 6, FALSE ), IFERROR(VLOOKUP($C9, '[1]Dettaglio pacchetti'!$A$1:$I$530, 6, FALSE), "") )} -> Azure Devops
C10: deploy.documentale_8emc02a_CORRETTIVA | D10: {=IFERROR( _xlfn.LET( _xlpm.risultato, IFERROR( _xlfn.XLOOKUP(TRIM(UPPER(G10)), TRIM(UPPER(Applicazioni!$C$1:$C$474)), Applicazioni!$B$1:$B$474 ), _xlfn.XLOOKUP( TRIM(UPPER( INDEX( _xlfn._xlws.FILTER('[1]Dettaglio pacchetti'!$B$1:$B$530, TRIM(UPPER('[1]Dettaglio pacchetti'!$E$1:$E$530))=TRIM(UPPER(G10)), "" ), 1) )), TRIM(UPPER(Applicazioni!$C$1:$C$474)), Applicazioni!$B$1:$B$474 ) ), IF(_xlpm.risultato=0, "", _xlpm.risultato) ), "" )} | E10: {=IF(TRIM($B10)="SG-ANAGRAFE", "Bugni Batte", IF(TRIM($B10)="DW01A", "Cauda", IFERROR( VLOOKUP( INDEX('[1]Dettaglio pacchetti'!$AB$1:$AB$530, _xlfn.AGGREGATE(15, 6, (ROW($1:$345))/(ISNUMBER(SEARCH('[1]Dettaglio pacchetti'!$AB$1:$AB$530, $C10))), 1) ) & "*", '[1]Dettaglio pacchetti'!$A$1:$I$530, 3, FALSE ), IFERROR(VLOOKUP($C10, '[1]Dettaglio pacchetti'!$A$1:$I$530, 3, FALSE), "") ) ) )} -> Rocca | F10: {=IF(TRIM($B10)="DW01A", "Rilascio EDW Estrattori", IFERROR( VLOOKUP( INDEX('[1]Dettaglio pacchetti'!$AB$1:$AB$530, _xlfn.AGGREGATE(15, 6, (ROW($1:$345))/(ISNUMBER(SEARCH('[1]Dettaglio pacchetti'!$AB$1:$AB$530, $C10))), 1) ) & "*", '[1]Dettaglio pacchetti'!$A$1:$I$530, 4, FALSE ), IFERROR(VLOOKUP($C10, '[1]Dettaglio pacchetti'!$A$1:$I$530, 4, FALSE), "") ) )} -> Rilascio Portale DocumentaleSinistri 8EMC02A | G10: {=IF(TRIM($B10)="DW01A", "EDW - Estrattori", IF(TRIM($B10)="SG-ANAGRAFE", "SIGEA Anagrafe", IFERROR( VLOOKUP( INDEX('[1]Dettaglio pacchetti'!$AB$1:$AB$530, _xlfn.AGGREGATE(15, 6, (ROW($1:$345))/(ISNUMBER(SEARCH('[1]Dettaglio pacchetti'!$AB$1:$AB$530, $C10))), 1) ) & "*", '[1]Dettaglio pacchetti'!$A$1:$I$530, 5, FALSE ), IFERROR(VLOOKUP($C10, '[1]Dettaglio pacchetti'!$A$1:$I$530, 5, FALSE), "") ) ) )} -> Portale Documentale Sinistri | I10: =IF(OR(AA10="", AB10=""), "", HYPERLINK(AA10, AB10)) -> deploy.documentale_8emc02a_CORRETTIVA | J10: =IF($AC10="", "", IF(ISNUMBER(SEARCH("Ikan", $AD10)), "", HYPERLINK("https://dev.azure.com/realeitesorg/" & $AC10, $AC10) ) ) -> it.ites.deploy.documentale | K10: =IF($AC10="", "", IF(ISNUMBER(SEARCH("Ikan", $AD10)), $AC10, "" ) ) | L10: {=IFERROR( VLOOKUP( INDEX('[1]Dettaglio pacchetti'!$AB$1:$AB$530, _xlfn.AGGREGATE(15, 6, ROW($1:$345)/(ISNUMBER(SEARCH('[1]Dettaglio pacchetti'!$AB$1:$AB$530, $C10))), 1) ) & "*", '[1]Dettaglio pacchetti'!$A$1:$I$530, 8, FALSE ), IFERROR(VLOOKUP($C10, '[1]Dettaglio pacchetti'!$A$1:$I$530, 8, FALSE), "") )} -> 23.00 | M10: {=IFERROR( VLOOKUP( INDEX('[1]Dettaglio pacchetti'!$AB$1:$AB$530, _xlfn.AGGREGATE(15, 6, ROW($1:$345)/(ISNUMBER(SEARCH('[1]Dettaglio pacchetti'!$AB$1:$AB$530, $C10))), 1) ) & "*", '[1]Dettaglio pacchetti'!$A$1:$I$530, 9, FALSE ), IFERROR(VLOOKUP($C10, '[1]Dettaglio pacchetti'!$A$1:$I$530, 9, FALSE), "") )} -> ear | O10: OK | P10: OK | AA10: {=IFERROR(VLOOKUP(INDEX('[1]Dettaglio pacchetti'!$AB$1:$AB$530, _xlfn.AGGREGATE(15, 6, (ROW($1:$345))/(ISNUMBER(SEARCH('[1]Dettaglio pacchetti'!$AB$1:$AB$530, $C10))), 1)) & "*", '[1]Dettaglio pacchetti'!$A$1:$N$530, 13, FALSE) & "", "")} -> https://dev.azure.com/realeitesorg/it.ites.deploy.documentale/_build?definitionId=5001 | AB10: {=IF(ISNUMBER(SEARCH("dev.azure.com", AA10)), IFERROR(VLOOKUP(INDEX('[1]Dettaglio pacchetti'!$AB$1:$AB$530, _xlfn.AGGREGATE(15, 6, (ROW($1:$345))/(ISNUMBER(SEARCH('[1]Dettaglio pacchetti'!$AB$1:$AB$530, $C10))), 1)) & "*", '[1]Dettaglio pacchetti'!$A$1:$N$530, 1, FALSE) & "", ""), "")} -> deploy.documentale_8emc02a_CORRETTIVA | AC10: {=IFERROR( VLOOKUP( INDEX('[1]Dettaglio pacchetti'!$AB$1:$AB$530, _xlfn.AGGREGATE(15,6,ROW($1:$345)/(ISNUMBER(SEARCH('[1]Dettaglio pacchetti'!$AB$1:$AB$530,$C10))),1)) & "*", '[1]Dettaglio pacchetti'!$A$1:$I$530, 7, FALSE ), IFERROR(VLOOKUP($C10, '[1]Dettaglio pacchetti'!$A$1:$I$530, 7, FALSE), "") )} -> it.ites.deploy.documentale | AD10: {=IFERROR( VLOOKUP( INDEX('[1]Dettaglio pacchetti'!$AB$1:$AB$530, _xlfn.AGGREGATE(15,6,ROW($1:$345)/(ISNUMBER(SEARCH('[1]Dettaglio pacchetti'!$AB$1:$AB$530,$C10))),1)) & "*", '[1]Dettaglio pacchetti'!$A$1:$I$530, 6, FALSE ), IFERROR(VLOOKUP($C10, '[1]Dettaglio pacchetti'!$A$1:$I$530, 6, FALSE), "") )} -> Azure Devops
C11: paspo_CORRETTIVA | D11: {=IFERROR( _xlfn.LET( _xlpm.risultato, IFERROR( _xlfn.XLOOKUP(TRIM(UPPER(G11)), TRIM(UPPER(Applicazioni!$C$1:$C$474)), Applicazioni!$B$1:$B$474 ), _xlfn.XLOOKUP( TRIM(UPPER( INDEX( _xlfn._xlws.FILTER('[1]Dettaglio pacchetti'!$B$1:$B$530, TRIM(UPPER('[1]Dettaglio pacchetti'!$E$1:$E$530))=TRIM(UPPER(G11)), "" ), 1) )), TRIM(UPPER(Applicazioni!$C$1:$C$474)), Applicazioni!$B$1:$B$474 ) ), IF(_xlpm.risultato=0, "", _xlpm.risultato) ), "" )} -> C20260821_0043 | E11: {=IF(TRIM($B11)="SG-ANAGRAFE", "Bugni Batte", IF(TRIM($B11)="DW01A", "Cauda", IFERROR( VLOOKUP( INDEX('[1]Dettaglio pacchetti'!$AB$1:$AB$530, _xlfn.AGGREGATE(15, 6, (ROW($1:$345))/(ISNUMBER(SEARCH('[1]Dettaglio pacchetti'!$AB$1:$AB$530, $C11))), 1) ) & "*", '[1]Dettaglio pacchetti'!$A$1:$I$530, 3, FALSE ), IFERROR(VLOOKUP($C11, '[1]Dettaglio pacchetti'!$A$1:$I$530, 3, FALSE), "") ) ) )} -> Treno Danni | F11: {=IF(TRIM($B11)="DW01A", "Rilascio EDW Estrattori", IFERROR( VLOOKUP( INDEX('[1]Dettaglio pacchetti'!$AB$1:$AB$530, _xlfn.AGGREGATE(15, 6, (ROW($1:$345))/(ISNUMBER(SEARCH('[1]Dettaglio pacchetti'!$AB$1:$AB$530, $C11))), 1) ) & "*", '[1]Dettaglio pacchetti'!$A$1:$I$530, 4, FALSE ), IFERROR(VLOOKUP($C11, '[1]Dettaglio pacchetti'!$A$1:$I$530, 4, FALSE), "") ) )} -> Rilascio Pass Portal 7PASPO | G11: {=IF(TRIM($B11)="DW01A", "EDW - Estrattori", IF(TRIM($B11)="SG-ANAGRAFE", "SIGEA Anagrafe", IFERROR( VLOOKUP( INDEX('[1]Dettaglio pacchetti'!$AB$1:$AB$530, _xlfn.AGGREGATE(15, 6, (ROW($1:$345))/(ISNUMBER(SEARCH('[1]Dettaglio pacchetti'!$AB$1:$AB$530, $C11))), 1) ) & "*", '[1]Dettaglio pacchetti'!$A$1:$I$530, 5, FALSE ), IFERROR(VLOOKUP($C11, '[1]Dettaglio pacchetti'!$A$1:$I$530, 5, FALSE), "") ) ) )} -> Multicanalità - Pass Portal | I11: =IF(OR(AA11="", AB11=""), "", HYPERLINK(AA11, AB11)) -> paspo_CORRETTIVA | J11: =IF($AC11="", "", IF(ISNUMBER(SEARCH("Ikan", $AD11)), "", HYPERLINK("https://dev.azure.com/realeitesorg/" & $AC11, $AC11) ) ) -> it.grma.rdna | K11: =IF($AC11="", "", IF(ISNUMBER(SEARCH("Ikan", $AD11)), $AC11, "" ) ) | L11: {=IFERROR( VLOOKUP( INDEX('[1]Dettaglio pacchetti'!$AB$1:$AB$530, _xlfn.AGGREGATE(15, 6, ROW($1:$345)/(ISNUMBER(SEARCH('[1]Dettaglio pacchetti'!$AB$1:$AB$530, $C11))), 1) ) & "*", '[1]Dettaglio pacchetti'!$A$1:$I$530, 8, FALSE ), IFERROR(VLOOKUP($C11, '[1]Dettaglio pacchetti'!$A$1:$I$530, 8, FALSE), "") )} -> 23.00 | M11: {=IFERROR( VLOOKUP( INDEX('[1]Dettaglio pacchetti'!$AB$1:$AB$530, _xlfn.AGGREGATE(15, 6, ROW($1:$345)/(ISNUMBER(SEARCH('[1]Dettaglio pacchetti'!$AB$1:$AB$530, $C11))), 1) ) & "*", '[1]Dettaglio pacchetti'!$A$1:$I$530, 9, FALSE ), IFERROR(VLOOKUP($C11, '[1]Dettaglio pacchetti'!$A$1:$I$530, 9, FALSE), "") )} -> ear | O11: OK | P11: OK | AA11: {=IFERROR(VLOOKUP(INDEX('[1]Dettaglio pacchetti'!$AB$1:$AB$530, _xlfn.AGGREGATE(15, 6, (ROW($1:$345))/(ISNUMBER(SEARCH('[1]Dettaglio pacchetti'!$AB$1:$AB$530, $C11))), 1)) & "*", '[1]Dettaglio pacchetti'!$A$1:$N$530, 13, FALSE) & "", "")} -> https://dev.azure.com/realeitesorg/it.grma.rdna/_build?definitionId=4415&_a=summary | AB11: {=IF(ISNUMBER(SEARCH("dev.azure.com", AA11)), IFERROR(VLOOKUP(INDEX('[1]Dettaglio pacchetti'!$AB$1:$AB$530, _xlfn.AGGREGATE(15, 6, (ROW($1:$345))/(ISNUMBER(SEARCH('[1]Dettaglio pacchetti'!$AB$1:$AB$530, $C11))), 1)) & "*", '[1]Dettaglio pacchetti'!$A$1:$N$530, 1, FALSE) & "", ""), "")} -> paspo_CORRETTIVA | AC11: {=IFERROR( VLOOKUP( INDEX('[1]Dettaglio pacchetti'!$AB$1:$AB$530, _xlfn.AGGREGATE(15,6,ROW($1:$345)/(ISNUMBER(SEARCH('[1]Dettaglio pacchetti'!$AB$1:$AB$530,$C11))),1)) & "*", '[1]Dettaglio pacchetti'!$A$1:$I$530, 7, FALSE ), IFERROR(VLOOKUP($C11, '[1]Dettaglio pacchetti'!$A$1:$I$530, 7, FALSE), "") )} -> it.grma.rdna | AD11: {=IFERROR( VLOOKUP( INDEX('[1]Dettaglio pacchetti'!$AB$1:$AB$530, _xlfn.AGGREGATE(15,6,ROW($1:$345)/(ISNUMBER(SEARCH('[1]Dettaglio pacchetti'!$AB$1:$AB$530,$C11))),1)) & "*", '[1]Dettaglio pacchetti'!$A$1:$I$530, 6, FALSE ), IFERROR(VLOOKUP($C11, '[1]Dettaglio pacchetti'!$A$1:$I$530, 6, FALSE), "") )} -> Azure Devops
C12: CARD2017_EVOLUTIVA | D12: {=IFERROR( _xlfn.LET( _xlpm.risultato, IFERROR( _xlfn.XLOOKUP(TRIM(UPPER(G12)), TRIM(UPPER(Applicazioni!$C$1:$C$474)), Applicazioni!$B$1:$B$474 ), _xlfn.XLOOKUP( TRIM(UPPER( INDEX( _xlfn._xlws.FILTER('[1]Dettaglio pacchetti'!$B$1:$B$530, TRIM(UPPER('[1]Dettaglio pacchetti'!$E$1:$E$530))=TRIM(UPPER(G12)), "" ), 1) )), TRIM(UPPER(Applicazioni!$C$1:$C$474)), Applicazioni!$B$1:$B$474 ) ), IF(_xlpm.risultato=0, "", _xlpm.risultato) ), "" )} -> C20260814_0040 | E12: {=IF(TRIM($B12)="SG-ANAGRAFE", "Bugni Batte", IF(TRIM($B12)="DW01A", "Cauda", IFERROR( VLOOKUP( INDEX('[1]Dettaglio pacchetti'!$AB$1:$AB$530, _xlfn.AGGREGATE(15, 6, (ROW($1:$345))/(ISNUMBER(SEARCH('[1]Dettaglio pacchetti'!$AB$1:$AB$530, $C12))), 1) ) & "*", '[1]Dettaglio pacchetti'!$A$1:$I$530, 3, FALSE ), IFERROR(VLOOKUP($C12, '[1]Dettaglio pacchetti'!$A$1:$I$530, 3, FALSE), "") ) ) )} -> Treno Sinistri | F12: {=IF(TRIM($B12)="DW01A", "Rilascio EDW Estrattori", IFERROR( VLOOKUP( INDEX('[1]Dettaglio pacchetti'!$AB$1:$AB$530, _xlfn.AGGREGATE(15, 6, (ROW($1:$345))/(ISNUMBER(SEARCH('[1]Dettaglio pacchetti'!$AB$1:$AB$530, $C12))), 1) ) & "*", '[1]Dettaglio pacchetti'!$A$1:$I$530, 4, FALSE ), IFERROR(VLOOKUP($C12, '[1]Dettaglio pacchetti'!$A$1:$I$530, 4, FALSE), "") ) )} -> Rilascio Sinistri Web - CARD2017 | G12: {=IF(TRIM($B12)="DW01A", "EDW - Estrattori", IF(TRIM($B12)="SG-ANAGRAFE", "SIGEA Anagrafe", IFERROR( VLOOKUP( INDEX('[1]Dettaglio pacchetti'!$AB$1:$AB$530, _xlfn.AGGREGATE(15, 6, (ROW($1:$345))/(ISNUMBER(SEARCH('[1]Dettaglio pacchetti'!$AB$1:$AB$530, $C12))), 1) ) & "*", '[1]Dettaglio pacchetti'!$A$1:$I$530, 5, FALSE ), IFERROR(VLOOKUP($C12, '[1]Dettaglio pacchetti'!$A$1:$I$530, 5, FALSE), "") ) ) )} -> SinistriWeb - Batch | I12: =IF(OR(AA12="", AB12=""), "", HYPERLINK(AA12, AB12)) -> card2017_EVOLUTIVA | J12: =IF($AC12="", "", IF(ISNUMBER(SEARCH("Ikan", $AD12)), "", HYPERLINK("https://dev.azure.com/realeitesorg/" & $AC12, $AC12) ) ) -> it.grma.claims | K12: =IF($AC12="", "", IF(ISNUMBER(SEARCH("Ikan", $AD12)), $AC12, "" ) ) | L12: {=IFERROR( VLOOKUP( INDEX('[1]Dettaglio pacchetti'!$AB$1:$AB$530, _xlfn.AGGREGATE(15, 6, ROW($1:$345)/(ISNUMBER(SEARCH('[1]Dettaglio pacchetti'!$AB$1:$AB$530, $C12))), 1) ) & "*", '[1]Dettaglio pacchetti'!$A$1:$I$530, 8, FALSE ), IFERROR(VLOOKUP($C12, '[1]Dettaglio pacchetti'!$A$1:$I$530, 8, FALSE), "") )} -> 23.00 | M12: {=IFERROR( VLOOKUP( INDEX('[1]Dettaglio pacchetti'!$AB$1:$AB$530, _xlfn.AGGREGATE(15, 6, ROW($1:$345)/(ISNUMBER(SEARCH('[1]Dettaglio pacchetti'!$AB$1:$AB$530, $C12))), 1) ) & "*", '[1]Dettaglio pacchetti'!$A$1:$I$530, 9, FALSE ), IFERROR(VLOOKUP($C12, '[1]Dettaglio pacchetti'!$A$1:$I$530, 9, FALSE), "") )} -> ear | O12: OK | P12: OK | AA12: {=IFERROR(VLOOKUP(INDEX('[1]Dettaglio pacchetti'!$AB$1:$AB$530, _xlfn.AGGREGATE(15, 6, (ROW($1:$345))/(ISNUMBER(SEARCH('[1]Dettaglio pacchetti'!$AB$1:$AB$530, $C12))), 1)) & "*", '[1]Dettaglio pacchetti'!$A$1:$N$530, 13, FALSE) & "", "")} -> https://dev.azure.com/realeitesorg/it.grma.claims/_build?definitionId=1938 | AB12: {=IF(ISNUMBER(SEARCH("dev.azure.com", AA12)), IFERROR(VLOOKUP(INDEX('[1]Dettaglio pacchetti'!$AB$1:$AB$530, _xlfn.AGGREGATE(15, 6, (ROW($1:$345))/(ISNUMBER(SEARCH('[1]Dettaglio pacchetti'!$AB$1:$AB$530, $C12))), 1)) & "*", '[1]Dettaglio pacchetti'!$A$1:$N$530, 1, FALSE) & "", ""), "")} -> card2017_EVOLUTIVA | AC12: {=IFERROR( VLOOKUP( INDEX('[1]Dettaglio pacchetti'!$AB$1:$AB$530, _xlfn.AGGREGATE(15,6,ROW($1:$345)/(ISNUMBER(SEARCH('[1]Dettaglio pacchetti'!$AB$1:$AB$530,$C12))),1)) & "*", '[1]Dettaglio pacchetti'!$A$1:$I$530, 7, FALSE ), IFERROR(VLOOKUP($C12, '[1]Dettaglio pacchetti'!$A$1:$I$530, 7, FALSE), "") )} -> it.grma.claims | AD12: {=IFERROR( VLOOKUP( INDEX('[1]Dettaglio pacchetti'!$AB$1:$AB$530, _xlfn.AGGREGATE(15,6,ROW($1:$345)/(ISNUMBER(SEARCH('[1]Dettaglio pacchetti'!$AB$1:$AB$530,$C12))),1)) & "*", '[1]Dettaglio pacchetti'!$A$1:$I$530, 6, FALSE ), IFERROR(VLOOKUP($C12, '[1]Dettaglio pacchetti'!$A$1:$I$530, 6, FALSE), "") )} -> Azure Devops
C13: CARD2017_EVOLUTIVA | D13: {=IFERROR( _xlfn.LET( _xlpm.risultato, IFERROR( _xlfn.XLOOKUP(TRIM(UPPER(G13)), TRIM(UPPER(Applicazioni!$C$1:$C$474)), Applicazioni!$B$1:$B$474 ), _xlfn.XLOOKUP( TRIM(UPPER( INDEX( _xlfn._xlws.FILTER('[1]Dettaglio pacchetti'!$B$1:$B$530, TRIM(UPPER('[1]Dettaglio pacchetti'!$E$1:$E$530))=TRIM(UPPER(G13)), "" ), 1) )), TRIM(UPPER(Applicazioni!$C$1:$C$474)), Applicazioni!$B$1:$B$474 ) ), IF(_xlpm.risultato=0, "", _xlpm.risultato) ), "" )} -> C20260814_0040 | E13: {=IF(TRIM($B13)="SG-ANAGRAFE", "Bugni Batte", IF(TRIM($B13)="DW01A", "Cauda", IFERROR( VLOOKUP( INDEX('[1]Dettaglio pacchetti'!$AB$1:$AB$530, _xlfn.AGGREGATE(15, 6, (ROW($1:$345))/(ISNUMBER(SEARCH('[1]Dettaglio pacchetti'!$AB$1:$AB$530, $C13))), 1) ) & "*", '[1]Dettaglio pacchetti'!$A$1:$I$530, 3, FALSE ), IFERROR(VLOOKUP($C13, '[1]Dettaglio pacchetti'!$A$1:$I$530, 3, FALSE), "") ) ) )} -> Treno Sinistri | F13: {=IF(TRIM($B13)="DW01A", "Rilascio EDW Estrattori", IFERROR( VLOOKUP( INDEX('[1]Dettaglio pacchetti'!$AB$1:$AB$530, _xlfn.AGGREGATE(15, 6, (ROW($1:$345))/(ISNUMBER(SEARCH('[1]Dettaglio pacchetti'!$AB$1:$AB$530, $C13))), 1) ) & "*", '[1]Dettaglio pacchetti'!$A$1:$I$530, 4, FALSE ), IFERROR(VLOOKUP($C13, '[1]Dettaglio pacchetti'!$A$1:$I$530, 4, FALSE), "") ) )} -> Rilascio Sinistri Web - CARD2017 | G13: {=IF(TRIM($B13)="DW01A", "EDW - Estrattori", IF(TRIM($B13)="SG-ANAGRAFE", "SIGEA Anagrafe", IFERROR( VLOOKUP( INDEX('[1]Dettaglio pacchetti'!$AB$1:$AB$530, _xlfn.AGGREGATE(15, 6, (ROW($1:$345))/(ISNUMBER(SEARCH('[1]Dettaglio pacchetti'!$AB$1:$AB$530, $C13))), 1) ) & "*", '[1]Dettaglio pacchetti'!$A$1:$I$530, 5, FALSE ), IFERROR(VLOOKUP($C13, '[1]Dettaglio pacchetti'!$A$1:$I$530, 5, FALSE), "") ) ) )} -> SinistriWeb - Batch | I13: =IF(OR(AA13="", AB13=""), "", HYPERLINK(AA13, AB13)) -> card2017_EVOLUTIVA | J13: =IF($AC13="", "", IF(ISNUMBER(SEARCH("Ikan", $AD13)), "", HYPERLINK("https://dev.azure.com/realeitesorg/" & $AC13, $AC13) ) ) -> it.grma.claims | K13: =IF($AC13="", "", IF(ISNUMBER(SEARCH("Ikan", $AD13)), $AC13, "" ) ) | L13: {=IFERROR( VLOOKUP( INDEX('[1]Dettaglio pacchetti'!$AB$1:$AB$530, _xlfn.AGGREGATE(15, 6, ROW($1:$345)/(ISNUMBER(SEARCH('[1]Dettaglio pacchetti'!$AB$1:$AB$530, $C13))), 1) ) & "*", '[1]Dettaglio pacchetti'!$A$1:$I$530, 8, FALSE ), IFERROR(VLOOKUP($C13, '[1]Dettaglio pacchetti'!$A$1:$I$530, 8, FALSE), "") )} -> 23.00 | M13: {=IFERROR( VLOOKUP( INDEX('[1]Dettaglio pacchetti'!$AB$1:$AB$530, _xlfn.AGGREGATE(15, 6, ROW($1:$345)/(ISNUMBER(SEARCH('[1]Dettaglio pacchetti'!$AB$1:$AB$530, $C13))), 1) ) & "*", '[1]Dettaglio pacchetti'!$A$1:$I$530, 9, FALSE ), IFERROR(VLOOKUP($C13, '[1]Dettaglio pacchetti'!$A$1:$I$530, 9, FALSE), "") )} -> ear | O13: OK | P13: OK | AA13: {=IFERROR(VLOOKUP(INDEX('[1]Dettaglio pacchetti'!$AB$1:$AB$530, _xlfn.AGGREGATE(15, 6, (ROW($1:$345))/(ISNUMBER(SEARCH('[1]Dettaglio pacchetti'!$AB$1:$AB$530, $C13))), 1)) & "*", '[1]Dettaglio pacchetti'!$A$1:$N$530, 13, FALSE) & "", "")} -> https://dev.azure.com/realeitesorg/it.grma.claims/_build?definitionId=1938 | AB13: {=IF(ISNUMBER(SEARCH("dev.azure.com", AA13)), IFERROR(VLOOKUP(INDEX('[1]Dettaglio pacchetti'!$AB$1:$AB$530, _xlfn.AGGREGATE(15, 6, (ROW($1:$345))/(ISNUMBER(SEARCH('[1]Dettaglio pacchetti'!$AB$1:$AB$530, $C13))), 1)) & "*", '[1]Dettaglio pacchetti'!$A$1:$N$530, 1, FALSE) & "", ""), "")} -> card2017_EVOLUTIVA | AC13: {=IFERROR( VLOOKUP( INDEX('[1]Dettaglio pacchetti'!$AB$1:$AB$530, _xlfn.AGGREGATE(15,6,ROW($1:$345)/(ISNUMBER(SEARCH('[1]Dettaglio pacchetti'!$AB$1:$AB$530,$C13))),1)) & "*", '[1]Dettaglio pacchetti'!$A$1:$I$530, 7, FALSE ), IFERROR(VLOOKUP($C13, '[1]Dettaglio pacchetti'!$A$1:$I$530, 7, FALSE), "") )} -> it.grma.claims | AD13: {=IFERROR( VLOOKUP( INDEX('[1]Dettaglio pacchetti'!$AB$1:$AB$530, _xlfn.AGGREGATE(15,6,ROW($1:$345)/(ISNUMBER(SEARCH('[1]Dettaglio pacchetti'!$AB$1:$AB$530,$C13))),1)) & "*", '[1]Dettaglio pacchetti'!$A$1:$I$530, 6, FALSE ), IFERROR(VLOOKUP($C13, '[1]Dettaglio pacchetti'!$A$1:$I$530, 6, FALSE), "") )} -> Azure Devops
C14: it.grma.web.pni2cloud.middlewarenew | D14: {=IFERROR( _xlfn.LET( _xlpm.risultato, IFERROR( _xlfn.XLOOKUP(TRIM(UPPER(G14)), TRIM(UPPER(Applicazioni!$C$1:$C$474)), Applicazioni!$B$1:$B$474 ), _xlfn.XLOOKUP( TRIM(UPPER( INDEX( _xlfn._xlws.FILTER('[1]Dettaglio pacchetti'!$B$1:$B$530, TRIM(UPPER('[1]Dettaglio pacchetti'!$E$1:$E$530))=TRIM(UPPER(G14)), "" ), 1) )), TRIM(UPPER(Applicazioni!$C$1:$C$474)), Applicazioni!$B$1:$B$474 ) ), IF(_xlpm.risultato=0, "", _xlpm.risultato) ), "" )} -> C20260824_0044 | E14: {=IF(TRIM($B14)="SG-ANAGRAFE", "Bugni Batte", IF(TRIM($B14)="DW01A", "Cauda", IFERROR( VLOOKUP( INDEX('[1]Dettaglio pacchetti'!$AB$1:$AB$530, _xlfn.AGGREGATE(15, 6, (ROW($1:$345))/(ISNUMBER(SEARCH('[1]Dettaglio pacchetti'!$AB$1:$AB$530, $C14))), 1) ) & "*", '[1]Dettaglio pacchetti'!$A$1:$I$530, 3, FALSE ), IFERROR(VLOOKUP($C14, '[1]Dettaglio pacchetti'!$A$1:$I$530, 3, FALSE), "") ) ) )} -> Team Digital-Chetta | F14: {=IF(TRIM($B14)="DW01A", "Rilascio EDW Estrattori", IFERROR( VLOOKUP( INDEX('[1]Dettaglio pacchetti'!$AB$1:$AB$530, _xlfn.AGGREGATE(15, 6, (ROW($1:$345))/(ISNUMBER(SEARCH('[1]Dettaglio pacchetti'!$AB$1:$AB$530, $C14))), 1) ) & "*", '[1]Dettaglio pacchetti'!$A$1:$I$530, 4, FALSE ), IFERROR(VLOOKUP($C14, '[1]Dettaglio pacchetti'!$A$1:$I$530, 4, FALSE), "") ) )} -> Rilascio pipeline middelwarenew | G14: {=IF(TRIM($B14)="DW01A", "EDW - Estrattori", IF(TRIM($B14)="SG-ANAGRAFE", "SIGEA Anagrafe", IFERROR( VLOOKUP( INDEX('[1]Dettaglio pacchetti'!$AB$1:$AB$530, _xlfn.AGGREGATE(15, 6, (ROW($1:$345))/(ISNUMBER(SEARCH('[1]Dettaglio pacchetti'!$AB$1:$AB$530, $C14))), 1) ) & "*", '[1]Dettaglio pacchetti'!$A$1:$I$530, 5, FALSE ), IFERROR(VLOOKUP($C14, '[1]Dettaglio pacchetti'!$A$1:$I$530, 5, FALSE), "") ) ) )} -> Siti Istituzionali | I14: =IF(OR(AA14="", AB14=""), "", HYPERLINK(AA14, AB14)) -> it.grma.web.pni2cloud.middlewarenew | J14: =IF($AC14="", "", IF(ISNUMBER(SEARCH("Ikan", $AD14)), "", HYPERLINK("https://dev.azure.com/realeitesorg/" & $AC14, $AC14) ) ) -> it.grma.web | K14: =IF($AC14="", "", IF(ISNUMBER(SEARCH("Ikan", $AD14)), $AC14, "" ) ) | L14: {=IFERROR( VLOOKUP( INDEX('[1]Dettaglio pacchetti'!$AB$1:$AB$530, _xlfn.AGGREGATE(15, 6, ROW($1:$345)/(ISNUMBER(SEARCH('[1]Dettaglio pacchetti'!$AB$1:$AB$530, $C14))), 1) ) & "*", '[1]Dettaglio pacchetti'!$A$1:$I$530, 8, FALSE ), IFERROR(VLOOKUP($C14, '[1]Dettaglio pacchetti'!$A$1:$I$530, 8, FALSE), "") )} -> 23.00 | M14: {=IFERROR( VLOOKUP( INDEX('[1]Dettaglio pacchetti'!$AB$1:$AB$530, _xlfn.AGGREGATE(15, 6, ROW($1:$345)/(ISNUMBER(SEARCH('[1]Dettaglio pacchetti'!$AB$1:$AB$530, $C14))), 1) ) & "*", '[1]Dettaglio pacchetti'!$A$1:$I$530, 9, FALSE ), IFERROR(VLOOKUP($C14, '[1]Dettaglio pacchetti'!$A$1:$I$530, 9, FALSE), "") )} -> ubuntu | O14: OK | P14: OK | AA14: {=IFERROR(VLOOKUP(INDEX('[1]Dettaglio pacchetti'!$AB$1:$AB$530, _xlfn.AGGREGATE(15, 6, (ROW($1:$345))/(ISNUMBER(SEARCH('[1]Dettaglio pacchetti'!$AB$1:$AB$530, $C14))), 1)) & "*", '[1]Dettaglio pacchetti'!$A$1:$N$530, 13, FALSE) & "", "")} -> https://dev.azure.com/realeitesorg/it.grma.web/_build?definitionId=795 | AB14: {=IF(ISNUMBER(SEARCH("dev.azure.com", AA14)), IFERROR(VLOOKUP(INDEX('[1]Dettaglio pacchetti'!$AB$1:$AB$530, _xlfn.AGGREGATE(15, 6, (ROW($1:$345))/(ISNUMBER(SEARCH('[1]Dettaglio pacchetti'!$AB$1:$AB$530, $C14))), 1)) & "*", '[1]Dettaglio pacchetti'!$A$1:$N$530, 1, FALSE) & "", ""), "")} -> it.grma.web.pni2cloud.middlewarenew | AC14: {=IFERROR( VLOOKUP( INDEX('[1]Dettaglio pacchetti'!$AB$1:$AB$530, _xlfn.AGGREGATE(15,6,ROW($1:$345)/(ISNUMBER(SEARCH('[1]Dettaglio pacchetti'!$AB$1:$AB$530,$C14))),1)) & "*", '[1]Dettaglio pacchetti'!$A$1:$I$530, 7, FALSE ), IFERROR(VLOOKUP($C14, '[1]Dettaglio pacchetti'!$A$1:$I$530, 7, FALSE), "") )} -> it.grma.web | AD14: {=IFERROR( VLOOKUP( INDEX('[1]Dettaglio pacchetti'!$AB$1:$AB$530, _xlfn.AGGREGATE(15,6,ROW($1:$345)/(ISNUMBER(SEARCH('[1]Dettaglio pacchetti'!$AB$1:$AB$530,$C14))),1)) & "*", '[1]Dettaglio pacchetti'!$A$1:$I$530, 6, FALSE ), IFERROR(VLOOKUP($C14, '[1]Dettaglio pacchetti'!$A$1:$I$530, 6, FALSE), "") )} -> Azure Devops
C15: APISinistri | D15: {=IFERROR( _xlfn.LET( _xlpm.risultato, IFERROR( _xlfn.XLOOKUP(TRIM(UPPER(G15)), TRIM(UPPER(Applicazioni!$C$1:$C$474)), Applicazioni!$B$1:$B$474 ), _xlfn.XLOOKUP( TRIM(UPPER( INDEX( _xlfn._xlws.FILTER('[1]Dettaglio pacchetti'!$B$1:$B$530, TRIM(UPPER('[1]Dettaglio pacchetti'!$E$1:$E$530))=TRIM(UPPER(G15)), "" ), 1) )), TRIM(UPPER(Applicazioni!$C$1:$C$474)), Applicazioni!$B$1:$B$474 ) ), IF(_xlpm.risultato=0, "", _xlpm.risultato) ), "" )} -> C20260806_0083 | E15: {=IF(TRIM($B15)="SG-ANAGRAFE", "Bugni Batte", IF(TRIM($B15)="DW01A", "Cauda", IFERROR( VLOOKUP( INDEX('[1]Dettaglio pacchetti'!$AB$1:$AB$530, _xlfn.AGGREGATE(15, 6, (ROW($1:$345))/(ISNUMBER(SEARCH('[1]Dettaglio pacchetti'!$AB$1:$AB$530, $C15))), 1) ) & "*", '[1]Dettaglio pacchetti'!$A$1:$I$530, 3, FALSE ), IFERROR(VLOOKUP($C15, '[1]Dettaglio pacchetti'!$A$1:$I$530, 3, FALSE), "") ) ) )} -> Martino | F15: {=IF(TRIM($B15)="DW01A", "Rilascio EDW Estrattori", IFERROR( VLOOKUP( INDEX('[1]Dettaglio pacchetti'!$AB$1:$AB$530, _xlfn.AGGREGATE(15, 6, (ROW($1:$345))/(ISNUMBER(SEARCH('[1]Dettaglio pacchetti'!$AB$1:$AB$530, $C15))), 1) ) & "*", '[1]Dettaglio pacchetti'!$A$1:$I$530, 4, FALSE ), IFERROR(VLOOKUP($C15, '[1]Dettaglio pacchetti'!$A$1:$I$530, 4, FALSE), "") ) )} -> Evoluzione Sistemi Integrazione APISinistri | G15: {=IF(TRIM($B15)="DW01A", "EDW - Estrattori", IF(TRIM($B15)="SG-ANAGRAFE", "SIGEA Anagrafe", IFERROR( VLOOKUP( INDEX('[1]Dettaglio pacchetti'!$AB$1:$AB$530, _xlfn.AGGREGATE(15, 6, (ROW($1:$345))/(ISNUMBER(SEARCH('[1]Dettaglio pacchetti'!$AB$1:$AB$530, $C15))), 1) ) & "*", '[1]Dettaglio pacchetti'!$A$1:$I$530, 5, FALSE ), IFERROR(VLOOKUP($C15, '[1]Dettaglio pacchetti'!$A$1:$I$530, 5, FALSE), "") ) ) )} -> Integrazione | I15: https://dev.azure.com/realeitesorg/it.integration/_build?definitionId=4506&_a=summary | J15: =IF($AC15="", "", IF(ISNUMBER(SEARCH("Ikan", $AD15)), "", HYPERLINK("https://dev.azure.com/realeitesorg/" & $AC15, $AC15) ) ) -> it.integration | K15: =IF($AC15="", "", IF(ISNUMBER(SEARCH("Ikan", $AD15)), $AC15, "" ) ) | L15: {=IFERROR( VLOOKUP( INDEX('[1]Dettaglio pacchetti'!$AB$1:$AB$530, _xlfn.AGGREGATE(15, 6, ROW($1:$345)/(ISNUMBER(SEARCH('[1]Dettaglio pacchetti'!$AB$1:$AB$530, $C15))), 1) ) & "*", '[1]Dettaglio pacchetti'!$A$1:$I$530, 8, FALSE ), IFERROR(VLOOKUP($C15, '[1]Dettaglio pacchetti'!$A$1:$I$530, 8, FALSE), "") )} -> 23.00 | M15: {=IFERROR( VLOOKUP( INDEX('[1]Dettaglio pacchetti'!$AB$1:$AB$530, _xlfn.AGGREGATE(15, 6, ROW($1:$345)/(ISNUMBER(SEARCH('[1]Dettaglio pacchetti'!$AB$1:$AB$530, $C15))), 1) ) & "*", '[1]Dettaglio pacchetti'!$A$1:$I$530, 9, FALSE ), IFERROR(VLOOKUP($C15, '[1]Dettaglio pacchetti'!$A$1:$I$530, 9, FALSE), "") )} -> aks | O15: OK | P15: OK | AA15: {=IFERROR(VLOOKUP(INDEX('[1]Dettaglio pacchetti'!$AB$1:$AB$530, _xlfn.AGGREGATE(15, 6, (ROW($1:$345))/(ISNUMBER(SEARCH('[1]Dettaglio pacchetti'!$AB$1:$AB$530, $C15))), 1)) & "*", '[1]Dettaglio pacchetti'!$A$1:$N$530, 13, FALSE) & "", "")} | AB15: {=IF(ISNUMBER(SEARCH("dev.azure.com", AA15)), IFERROR(VLOOKUP(INDEX('[1]Dettaglio pacchetti'!$AB$1:$AB$530, _xlfn.AGGREGATE(15, 6, (ROW($1:$345))/(ISNUMBER(SEARCH('[1]Dettaglio pacchetti'!$AB$1:$AB$530, $C15))), 1)) & "*", '[1]Dettaglio pacchetti'!$A$1:$N$530, 1, FALSE) & "", ""), "")} | AC15: {=IFERROR( VLOOKUP( INDEX('[1]Dettaglio pacchetti'!$AB$1:$AB$530, _xlfn.AGGREGATE(15,6,ROW($1:$345)/(ISNUMBER(SEARCH('[1]Dettaglio pacchetti'!$AB$1:$AB$530,$C15))),1)) & "*", '[1]Dettaglio pacchetti'!$A$1:$I$530, 7, FALSE ), IFERROR(VLOOKUP($C15, '[1]Dettaglio pacchetti'!$A$1:$I$530, 7, FALSE), "") )} -> it.integration | AD15: {=IFERROR( VLOOKUP( INDEX('[1]Dettaglio pacchetti'!$AB$1:$AB$530, _xlfn.AGGREGATE(15,6,ROW($1:$345)/(ISNUMBER(SEARCH('[1]Dettaglio pacchetti'!$AB$1:$AB$530,$C15))),1)) & "*", '[1]Dettaglio pacchetti'!$A$1:$I$530, 6, FALSE ), IFERROR(VLOOKUP($C15, '[1]Dettaglio pacchetti'!$A$1:$I$530, 6, FALSE), "") )} -> Azure Devops
C16: EAIJcapsWrapper | D16: {=IFERROR( _xlfn.LET( _xlpm.risultato, IFERROR( _xlfn.XLOOKUP(TRIM(UPPER(G16)), TRIM(UPPER(Applicazioni!$C$1:$C$474)), Applicazioni!$B$1:$B$474 ), _xlfn.XLOOKUP( TRIM(UPPER( INDEX( _xlfn._xlws.FILTER('[1]Dettaglio pacchetti'!$B$1:$B$530, TRIM(UPPER('[1]Dettaglio pacchetti'!$E$1:$E$530))=TRIM(UPPER(G16)), "" ), 1) )), TRIM(UPPER(Applicazioni!$C$1:$C$474)), Applicazioni!$B$1:$B$474 ) ), IF(_xlpm.risultato=0, "", _xlpm.risultato) ), "" )} -> C20260806_0083 | E16: {=IF(TRIM($B16)="SG-ANAGRAFE", "Bugni Batte", IF(TRIM($B16)="DW01A", "Cauda", IFERROR( VLOOKUP( INDEX('[1]Dettaglio pacchetti'!$AB$1:$AB$530, _xlfn.AGGREGATE(15, 6, (ROW($1:$345))/(ISNUMBER(SEARCH('[1]Dettaglio pacchetti'!$AB$1:$AB$530, $C16))), 1) ) & "*", '[1]Dettaglio pacchetti'!$A$1:$I$530, 3, FALSE ), IFERROR(VLOOKUP($C16, '[1]Dettaglio pacchetti'!$A$1:$I$530, 3, FALSE), "") ) ) )} -> Martino | F16: {=IF(TRIM($B16)="DW01A", "Rilascio EDW Estrattori", IFERROR( VLOOKUP( INDEX('[1]Dettaglio pacchetti'!$AB$1:$AB$530, _xlfn.AGGREGATE(15, 6, (ROW($1:$345))/(ISNUMBER(SEARCH('[1]Dettaglio pacchetti'!$AB$1:$AB$530, $C16))), 1) ) & "*", '[1]Dettaglio pacchetti'!$A$1:$I$530, 4, FALSE ), IFERROR(VLOOKUP($C16, '[1]Dettaglio pacchetti'!$A$1:$I$530, 4, FALSE), "") ) )} -> Evoluzione Sistemi Integrazione JCAPS wrapper | G16: {=IF(TRIM($B16)="DW01A", "EDW - Estrattori", IF(TRIM($B16)="SG-ANAGRAFE", "SIGEA Anagrafe", IFERROR( VLOOKUP( INDEX('[1]Dettaglio pacchetti'!$AB$1:$AB$530, _xlfn.AGGREGATE(15, 6, (ROW($1:$345))/(ISNUMBER(SEARCH('[1]Dettaglio pacchetti'!$AB$1:$AB$530, $C16))), 1) ) & "*", '[1]Dettaglio pacchetti'!$A$1:$I$530, 5, FALSE ), IFERROR(VLOOKUP($C16, '[1]Dettaglio pacchetti'!$A$1:$I$530, 5, FALSE), "") ) ) )} -> Integrazione | I16: https://dev.azure.com/realeitesorg/it.integration/_build?definitionId=3176 | J16: =IF($AC16="", "", IF(ISNUMBER(SEARCH("Ikan", $AD16)), "", HYPERLINK("https://dev.azure.com/realeitesorg/" & $AC16, $AC16) ) ) -> it.integration | K16: =IF($AC16="", "", IF(ISNUMBER(SEARCH("Ikan", $AD16)), $AC16, "" ) ) | L16: {=IFERROR( VLOOKUP( INDEX('[1]Dettaglio pacchetti'!$AB$1:$AB$530, _xlfn.AGGREGATE(15, 6, ROW($1:$345)/(ISNUMBER(SEARCH('[1]Dettaglio pacchetti'!$AB$1:$AB$530, $C16))), 1) ) & "*", '[1]Dettaglio pacchetti'!$A$1:$I$530, 8, FALSE ), IFERROR(VLOOKUP($C16, '[1]Dettaglio pacchetti'!$A$1:$I$530, 8, FALSE), "") )} -> 23.00 | M16: {=IFERROR( VLOOKUP( INDEX('[1]Dettaglio pacchetti'!$AB$1:$AB$530, _xlfn.AGGREGATE(15, 6, ROW($1:$345)/(ISNUMBER(SEARCH('[1]Dettaglio pacchetti'!$AB$1:$AB$530, $C16))), 1) ) & "*", '[1]Dettaglio pacchetti'!$A$1:$I$530, 9, FALSE ), IFERROR(VLOOKUP($C16, '[1]Dettaglio pacchetti'!$A$1:$I$530, 9, FALSE), "") )} -> aks | O16: OK | P16: OK | AA16: {=IFERROR(VLOOKUP(INDEX('[1]Dettaglio pacchetti'!$AB$1:$AB$530, _xlfn.AGGREGATE(15, 6, (ROW($1:$345))/(ISNUMBER(SEARCH('[1]Dettaglio pacchetti'!$AB$1:$AB$530, $C16))), 1)) & "*", '[1]Dettaglio pacchetti'!$A$1:$N$530, 13, FALSE) & "", "")} | AB16: {=IF(ISNUMBER(SEARCH("dev.azure.com", AA16)), IFERROR(VLOOKUP(INDEX('[1]Dettaglio pacchetti'!$AB$1:$AB$530, _xlfn.AGGREGATE(15, 6, (ROW($1:$345))/(ISNUMBER(SEARCH('[1]Dettaglio pacchetti'!$AB$1:$AB$530, $C16))), 1)) & "*", '[1]Dettaglio pacchetti'!$A$1:$N$530, 1, FALSE) & "", ""), "")} | AC16: {=IFERROR( VLOOKUP( INDEX('[1]Dettaglio pacchetti'!$AB$1:$AB$530, _xlfn.AGGREGATE(15,6,ROW($1:$345)/(ISNUMBER(SEARCH('[1]Dettaglio pacchetti'!$AB$1:$AB$530,$C16))),1)) & "*", '[1]Dettaglio pacchetti'!$A$1:$I$530, 7, FALSE ), IFERROR(VLOOKUP($C16, '[1]Dettaglio pacchetti'!$A$1:$I$530, 7, FALSE), "") )} -> it.integration | AD16: {=IFERROR( VLOOKUP( INDEX('[1]Dettaglio pacchetti'!$AB$1:$AB$530, _xlfn.AGGREGATE(15,6,ROW($1:$345)/(ISNUMBER(SEARCH('[1]Dettaglio pacchetti'!$AB$1:$AB$530,$C16))),1)) & "*", '[1]Dettaglio pacchetti'!$A$1:$I$530, 6, FALSE ), IFERROR(VLOOKUP($C16, '[1]Dettaglio pacchetti'!$A$1:$I$530, 6, FALSE), "") )} -> Azure Devops
